2025-11-01 20:43:02,386 - app - ERROR - Exception on /datasets/top-datasets [GET]
Traceback (most recent call last):
  File "/home/juan-antonio/Escritorio/PROYECTO/syssoft-hub/venv/lib/python3.12/site-packages/flask/app.py", line 1511, in wsgi_app
    response = self.full_dispatch_request()
               ^^^^^^^^^^^^^^^^^^^^^^^^^^^^
  File "/home/juan-antonio/Escritorio/PROYECTO/syssoft-hub/venv/lib/python3.12/site-packages/flask/app.py", line 919, in full_dispatch_request
    rv = self.handle_user_exception(e)
         ^^^^^^^^^^^^^^^^^^^^^^^^^^^^^
  File "/home/juan-antonio/Escritorio/PROYECTO/syssoft-hub/venv/lib/python3.12/site-packages/flask_restful/__init__.py", line 298, in error_router
    return original_handler(e)
           ^^^^^^^^^^^^^^^^^^^
  File "/home/juan-antonio/Escritorio/PROYECTO/syssoft-hub/venv/lib/python3.12/site-packages/flask/app.py", line 917, in full_dispatch_request
    rv = self.dispatch_request()
         ^^^^^^^^^^^^^^^^^^^^^^^
  File "/home/juan-antonio/Escritorio/PROYECTO/syssoft-hub/venv/lib/python3.12/site-packages/flask/app.py", line 902, in dispatch_request
    return self.ensure_sync(self.view_functions[rule.endpoint])(**view_args)  # type: ignore[no-any-return]
           ^^^^^^^^^^^^^^^^^^^^^^^^^^^^^^^^^^^^^^^^^^^^^^^^^^^^^^^^^^^^^^^^^
  File "/home/juan-antonio/Escritorio/PROYECTO/syssoft-hub/venv/lib/python3.12/site-packages/flask_login/utils.py", line 290, in decorated_view
    return current_app.ensure_sync(func)(*args, **kwargs)
           ^^^^^^^^^^^^^^^^^^^^^^^^^^^^^^^^^^^^^^^^^^^^^^
  File "/home/juan-antonio/Escritorio/PROYECTO/syssoft-hub/app/modules/dataset/routes.py", line 278, in view_top_datasets
    datasets = dataset_service.get_top_datasets(limit=5)
               ^^^^^^^^^^^^^^^^^^^^^^^^^^^^^^^^^^^^^^^^^
  File "/home/juan-antonio/Escritorio/PROYECTO/syssoft-hub/app/modules/dataset/services.py", line 144, in get_top_datasets
    return self.repository.get_top_datasets(limit=limit)
           ^^^^^^^^^^^^^^^^^^^^^^^^^^^^^^^^
AttributeError: 'DataSetRepository' object has no attribute 'get_top_datasets'
2025-11-01 20:43:02,392 - app - ERROR - Internal Server Error: 500 Internal Server Error: The server encountered an internal error and was unable to complete your request. Either the server is overloaded or there is an error in the application.
2025-11-01 20:48:39,952 - app - ERROR - Exception on /datasets/top-datasets [GET]
Traceback (most recent call last):
  File "/home/juan-antonio/Escritorio/PROYECTO/syssoft-hub/venv/lib/python3.12/site-packages/flask/app.py", line 1511, in wsgi_app
    response = self.full_dispatch_request()
               ^^^^^^^^^^^^^^^^^^^^^^^^^^^^
  File "/home/juan-antonio/Escritorio/PROYECTO/syssoft-hub/venv/lib/python3.12/site-packages/flask/app.py", line 919, in full_dispatch_request
    rv = self.handle_user_exception(e)
         ^^^^^^^^^^^^^^^^^^^^^^^^^^^^^
  File "/home/juan-antonio/Escritorio/PROYECTO/syssoft-hub/venv/lib/python3.12/site-packages/flask_restful/__init__.py", line 298, in error_router
    return original_handler(e)
           ^^^^^^^^^^^^^^^^^^^
  File "/home/juan-antonio/Escritorio/PROYECTO/syssoft-hub/venv/lib/python3.12/site-packages/flask/app.py", line 917, in full_dispatch_request
    rv = self.dispatch_request()
         ^^^^^^^^^^^^^^^^^^^^^^^
  File "/home/juan-antonio/Escritorio/PROYECTO/syssoft-hub/venv/lib/python3.12/site-packages/flask/app.py", line 902, in dispatch_request
    return self.ensure_sync(self.view_functions[rule.endpoint])(**view_args)  # type: ignore[no-any-return]
           ^^^^^^^^^^^^^^^^^^^^^^^^^^^^^^^^^^^^^^^^^^^^^^^^^^^^^^^^^^^^^^^^^
  File "/home/juan-antonio/Escritorio/PROYECTO/syssoft-hub/venv/lib/python3.12/site-packages/flask_login/utils.py", line 290, in decorated_view
    return current_app.ensure_sync(func)(*args, **kwargs)
           ^^^^^^^^^^^^^^^^^^^^^^^^^^^^^^^^^^^^^^^^^^^^^^
  File "/home/juan-antonio/Escritorio/PROYECTO/syssoft-hub/app/modules/dataset/routes.py", line 278, in view_top_datasets
    datasets = dataset_service.get_top_datasets(limit=5)
               ^^^^^^^^^^^^^^^^^^^^^^^^^^^^^^^^^^^^^^^^^
  File "/home/juan-antonio/Escritorio/PROYECTO/syssoft-hub/app/modules/dataset/services.py", line 144, in get_top_datasets
    return self.repository.get_top_datasets(limit=limit)
           ^^^^^^^^^^^^^^^^^^^^^^^^^^^^^^^^
AttributeError: 'DataSetRepository' object has no attribute 'get_top_datasets'
2025-11-01 20:48:39,955 - app - ERROR - Internal Server Error: 500 Internal Server Error: The server encountered an internal error and was unable to complete your request. Either the server is overloaded or there is an error in the application.
2025-11-01 20:49:33,319 - app - ERROR - Exception on /datasets/top-datasets [GET]
Traceback (most recent call last):
  File "/home/juan-antonio/Escritorio/PROYECTO/syssoft-hub/venv/lib/python3.12/site-packages/flask/app.py", line 1511, in wsgi_app
    response = self.full_dispatch_request()
               ^^^^^^^^^^^^^^^^^^^^^^^^^^^^
  File "/home/juan-antonio/Escritorio/PROYECTO/syssoft-hub/venv/lib/python3.12/site-packages/flask/app.py", line 919, in full_dispatch_request
    rv = self.handle_user_exception(e)
         ^^^^^^^^^^^^^^^^^^^^^^^^^^^^^
  File "/home/juan-antonio/Escritorio/PROYECTO/syssoft-hub/venv/lib/python3.12/site-packages/flask_restful/__init__.py", line 298, in error_router
    return original_handler(e)
           ^^^^^^^^^^^^^^^^^^^
  File "/home/juan-antonio/Escritorio/PROYECTO/syssoft-hub/venv/lib/python3.12/site-packages/flask/app.py", line 917, in full_dispatch_request
    rv = self.dispatch_request()
         ^^^^^^^^^^^^^^^^^^^^^^^
  File "/home/juan-antonio/Escritorio/PROYECTO/syssoft-hub/venv/lib/python3.12/site-packages/flask/app.py", line 902, in dispatch_request
    return self.ensure_sync(self.view_functions[rule.endpoint])(**view_args)  # type: ignore[no-any-return]
           ^^^^^^^^^^^^^^^^^^^^^^^^^^^^^^^^^^^^^^^^^^^^^^^^^^^^^^^^^^^^^^^^^
  File "/home/juan-antonio/Escritorio/PROYECTO/syssoft-hub/venv/lib/python3.12/site-packages/flask_login/utils.py", line 290, in decorated_view
    return current_app.ensure_sync(func)(*args, **kwargs)
           ^^^^^^^^^^^^^^^^^^^^^^^^^^^^^^^^^^^^^^^^^^^^^^
  File "/home/juan-antonio/Escritorio/PROYECTO/syssoft-hub/app/modules/dataset/routes.py", line 278, in view_top_datasets
    datasets = dataset_service.get_top_datasets(limit=5)
               ^^^^^^^^^^^^^^^^^^^^^^^^^^^^^^^^^^^^^^^^^
  File "/home/juan-antonio/Escritorio/PROYECTO/syssoft-hub/app/modules/dataset/services.py", line 144, in get_top_datasets
    return self.repository.get_top_datasets(limit=limit)
           ^^^^^^^^^^^^^^^^^^^^^^^^^^^^^^^^
AttributeError: 'DataSetRepository' object has no attribute 'get_top_datasets'
2025-11-01 20:49:33,320 - app - ERROR - Internal Server Error: 500 Internal Server Error: The server encountered an internal error and was unable to complete your request. Either the server is overloaded or there is an error in the application.
2025-11-01 20:52:50,258 - app - ERROR - Exception on /datasets/top-datasets [GET]
Traceback (most recent call last):
  File "/home/juan-antonio/Escritorio/PROYECTO/syssoft-hub/venv/lib/python3.12/site-packages/flask/app.py", line 1511, in wsgi_app
    response = self.full_dispatch_request()
               ^^^^^^^^^^^^^^^^^^^^^^^^^^^^
  File "/home/juan-antonio/Escritorio/PROYECTO/syssoft-hub/venv/lib/python3.12/site-packages/flask/app.py", line 919, in full_dispatch_request
    rv = self.handle_user_exception(e)
         ^^^^^^^^^^^^^^^^^^^^^^^^^^^^^
  File "/home/juan-antonio/Escritorio/PROYECTO/syssoft-hub/venv/lib/python3.12/site-packages/flask_restful/__init__.py", line 298, in error_router
    return original_handler(e)
           ^^^^^^^^^^^^^^^^^^^
  File "/home/juan-antonio/Escritorio/PROYECTO/syssoft-hub/venv/lib/python3.12/site-packages/flask/app.py", line 917, in full_dispatch_request
    rv = self.dispatch_request()
         ^^^^^^^^^^^^^^^^^^^^^^^
  File "/home/juan-antonio/Escritorio/PROYECTO/syssoft-hub/venv/lib/python3.12/site-packages/flask/app.py", line 902, in dispatch_request
    return self.ensure_sync(self.view_functions[rule.endpoint])(**view_args)  # type: ignore[no-any-return]
           ^^^^^^^^^^^^^^^^^^^^^^^^^^^^^^^^^^^^^^^^^^^^^^^^^^^^^^^^^^^^^^^^^
  File "/home/juan-antonio/Escritorio/PROYECTO/syssoft-hub/venv/lib/python3.12/site-packages/flask_login/utils.py", line 290, in decorated_view
    return current_app.ensure_sync(func)(*args, **kwargs)
           ^^^^^^^^^^^^^^^^^^^^^^^^^^^^^^^^^^^^^^^^^^^^^^
  File "/home/juan-antonio/Escritorio/PROYECTO/syssoft-hub/app/modules/dataset/routes.py", line 278, in view_top_datasets
    datasets = dataset_service.get_top_datasets(limit=5)
               ^^^^^^^^^^^^^^^^^^^^^^^^^^^^^^^^^^^^^^^^^
  File "/home/juan-antonio/Escritorio/PROYECTO/syssoft-hub/app/modules/dataset/services.py", line 144, in get_top_datasets
    return self.repository.get_top_datasets(limit=limit)
           ^^^^^^^^^^^^^^^^^^^^^^^^^^^^^^^^
AttributeError: 'DataSetRepository' object has no attribute 'get_top_datasets'
2025-11-01 20:52:50,264 - app - ERROR - Internal Server Error: 500 Internal Server Error: The server encountered an internal error and was unable to complete your request. Either the server is overloaded or there is an error in the application.
